Workbook

Sheet Checklist
A1: Professional Python ISP — Source-Backed Implementation Checklist
A2: 151 auditable items against openISP commit d4947e1. IDs 1–117 are frozen; 7a and 79a are non-renumbering splits; new gaps are 118–149. Table, formulas, validation and conditional formatting reserve rows through 300.
A3: Status | B3: ID | C3: Category | D3: Scope | E3: Requirement level | F3: Applicability | G3: Priority | H3: Effort | I3: Capability | J3: Source fit | K3: Primary source | L3: Page / section | M3: Implementation checklist | N3: Acceptance criteria | O3: Verification method | P3: Dependencies | Q3: Deliverable / module | R3: Primary URL | S3: Supplemental source | T3: Supp. page / section | U3: Supplemental URL | V3: Required artifact | W3: IP / license status | X3: Owner | Y3: Target milestone | Z3: Notes
A4: Not started | B4: 1 | C4: 1. RAW front end | D4: 1. Core ISP algorithms | E4: Core | F4: All configurations unless marked optional or sensor-specific | G4: P0 | H4: M | I4: RAW bit-depth normalization and white-level handling | J4: Direct | K4: S02 — Digital Negative (DNG) Specification 1.7.1.0 | L4: pp. 29, 99 | M4: Read WhiteLevel per channel/CFA plane, subtract black, scale active signal to a common linear working range, and clip only after normalization. | N4: Automated tests and representative RAW fixtures demonstrate raw bit-depth normalization and white-level handling across declared modes, with documented tolerances and no regression in adjacent stages. | O4: Unit tests plus fixed RAW/image regression fixtures; record configuration, metrics and artifacts. | Q4: Python module, typed configuration and tests for raw bit-depth normalization and white-level handling | R4: https://helpx.adobe.com/content/dam/help/en/camera-raw/digital-negative/jcr_content/root/content/flex/items/position/position-par/download_section_733958301/download-1/DNG_Spec_1_7_1_0.pdf | V4: None | W4: Source/provenance review required before commercial release
A5: Not started | B5: 2 | C5: 1. RAW front end | D5: 1. Core ISP algorithms | E5: Core | F5: All configurations unless marked optional or sensor-specific | G5: P0 | H5: M | I5: Sensor linearization | J5: Direct | K5: S02 — Digital Negative (DNG) Specification 1.7.1.0 | L5: pp. 27, 99 | M5: Apply LinearizationTable before black subtraction/rescaling. Preserve enough precision for later color and HDR work. | N5: Automated tests and representative RAW fixtures demonstrate sensor linearization across declared modes, with documented tolerances and no regression in adjacent stages. | O5: Unit tests plus fixed RAW/image regression fixtures; record configuration, metrics and artifacts. | Q5: Python module, typed configuration and tests for sensor linearization | R5: https://helpx.adobe.com/content/dam/help/en/camera-raw/digital-negative/jcr_content/root/content/flex/items/position/position-par/download_section_733958301/download-1/DNG_Spec_1_7_1_0.pdf | V5: None | W5: Source/provenance review required before commercial release
A6: Not started | B6: 3 | C6: 1. RAW front end | D6: 1. Core ISP algorithms | E6: Core | F6: All configurations unless marked optional or sensor-specific | G6: P0 | H6: M | I6: Companding/decompanding | J6: Direct | K6: S02 — Digital Negative (DNG) Specification 1.7.1.0 | L6: pp. 113–114 | M6: Represent the inverse sensor transfer with MapTable or MapPolynomial opcodes; apply it before operations that assume scene-linear values. | N6: Automated tests and representative RAW fixtures demonstrate companding/decompanding across declared modes, with documented tolerances and no regression in adjacent stages. | O6: Unit tests plus fixed RAW/image regression fixtures; record configuration, metrics and artifacts. | Q6: Python module, typed configuration and tests for companding/decompanding | R6: https://helpx.adobe.com/content/dam/help/en/camera-raw/digital-negative/jcr_content/root/content/flex/items/position/position-par/download_section_733958301/download-1/DNG_Spec_1_7_1_0.pdf | V6: None | W6: Source/provenance review required before commercial release
A7: Not started | B7: 4 | C7: 1. RAW front end | D7: 1. Core ISP algorithms | E7: Core | F7: All configurations unless marked optional or sensor-specific | G7: P0 | H7: M | I7: Optical-black-region processing | J7: Direct | K7: S03 — V4L2 RKISP1 parameters and 3A statistics | L7: rkisp1_cif_isp_bls_config | M7: Measure the masked/optical-black windows per Bayer position and subtract their means; retain fixed offsets as a fallback. | N7: Automated tests and representative RAW fixtures demonstrate optical-black-region processing across declared modes, with documented tolerances and no regression in adjacent stages. | O7: Unit tests plus fixed RAW/image regression fixtures; record configuration, metrics and artifacts. | Q7: Python module, typed configuration and tests for optical-black-region processing | R7: https://docs.kernel.org/userspace-api/media/v4l/metafmt-rkisp1.html#:~:text=Automatic%20mode%20activated%20means%20that%20the%20measured%20values%20are%20subtracted | S7: S02 — Digital Negative (DNG) Specification 1.7.1.0 | T7: p. 44 (MaskedAreas) | U7: https://helpx.adobe.com/content/dam/help/en/camera-raw/digital-negative/jcr_content/root/content/flex/items/position/position-par/download_section_733958301/download-1/DNG_Spec_1_7_1_0.pdf | V7: None | W7: Source/provenance review required before commercial release
A8: Not started | B8: 5 | C8: 1. RAW front end | D8: 1. Core ISP algorithms | E8: Core | F8: All configurations unless marked optional or sensor-specific | G8: P0 | H8: M | I8: Row/column fixed-pattern noise correction | J8: Direct | K8: S02 — Digital Negative (DNG) Specification 1.7.1.0 | L8: pp. 116–119 | M8: Estimate row/column offsets or gains from dark/flat stacks and apply DeltaPerRow/Column or ScalePerRow/Column equivalents before demosaic. | N8: Automated tests and representative RAW fixtures demonstrate row/column fixed-pattern noise correction across declared modes, with documented tolerances and no regression in adjacent stages. | O8: Unit tests plus fixed RAW/image regression fixtures; record configuration, metrics and artifacts. | Q8: Python module, typed configuration and tests for row/column fixed-pattern noise correction | R8: https://helpx.adobe.com/content/dam/help/en/camera-raw/digital-negative/jcr_content/root/content/flex/items/position/position-par/download_section_733958301/download-1/DNG_Spec_1_7_1_0.pdf | S8: S21 — EMVA Standard 1288 Release 3.0 | T8: pp. 21–25 (DSNU/PRNU methods) | U8: https://www.emva.org/wp-content/uploads/EMVA1288-3.0.pdf | V8: None | W8: Source/provenance review required before commercial release
A9: Not started | B9: 6 | C9: 1. RAW front end | D9: 1. Core ISP algorithms | E9: Core | F9: All configurations unless marked optional or sensor-specific | G9: P0 | H9: M | I9: Green-channel imbalance/equalization | J9: Direct | K9: S01 — Camera Algorithm and Tuning Guide | L9: pp. 22–23 | M9: Estimate the Gr/Gb imbalance versus signal/lux; low-pass only the imbalance component and make strength lux-dependent to avoid unnecessary blur. | N9: Automated tests and representative RAW fixtures demonstrate green-channel imbalance/equalization across declared modes, with documented tolerances and no regression in adjacent stages. | O9: Unit tests plus fixed RAW/image regression fixtures; record configuration, metrics and artifacts. | Q9: Python module, typed configuration and tests for green-channel imbalance/equalization | R9: https://datasheets.raspberrypi.com/camera/raspberry-pi-camera-guide.pdf | V9: None | W9: Source/provenance review required before commercial release
A10: Not started | B10: 7 | C10: 1. RAW front end | D10: 1. Core ISP algorithms | E10: Core | F10: All configurations unless marked optional or sensor-specific | G10: P0 | H10: M | I10: Lens-shading correction | J10: Direct | K10: S01 — Camera Algorithm and Tuning Guide | L10: pp. 37–41 | M10: Use calibrated per-channel gain grids and spatial interpolation in sensor coordinates; bound gains and verify residual flat-field uniformity. | N10: Automated tests and representative RAW fixtures demonstrate lens-shading correction across declared modes, with documented tolerances and no regression in adjacent stages. | O10: Unit tests plus fixed RAW/image regression fixtures; record configuration, metrics and artifacts. | Q10: Python module, typed configuration and tests for lens-shading correction | R10: https://datasheets.raspberrypi.com/camera/raspberry-pi-camera-guide.pdf | S10: S02 — Digital Negative (DNG) Specification 1.7.1.0 | T10: p. 115 (GainMap) | U10: https://helpx.adobe.com/content/dam/help/en/camera-raw/digital-negative/jcr_content/root/content/flex/items/position/position-par/download_section_733958301/download-1/DNG_Spec_1_7_1_0.pdf | V10: None | W10: Source/provenance review required before commercial release
A11: Not started | B11: 7a | C11: 1. RAW front end | D11: 2. Sensor and lens integration | E11: Core | F11: Per sensor/lens module when colour shading varies with illuminant, CRA, focus or zoom | G11: P0 | H11: L | I11: CCT/CRA-dependent color-shading correction | J11: Direct | K11: S01 — Camera Algorithm and Tuning Guide | L11: pp. 37–41 | M11: Interpolate calibrated color-shading tables across illuminant/CCT and, where required, chief-ray angle or lens state; normalize luminance and colour components separately so flat-field chromaticity remains stable. | N11: Across the calibrated CCT/lens grid and interpolation midpoints, a uniform target meets the product's center-to-corner luminance and chromaticity-error limits without double-counting item 7. | O11: Uniform-field captures at every calibration node plus withheld CCT/lens-state interpolation points; report per-channel residual maps. | P11: 7, 24 | Q11: Python module, typed configuration and tests for cct/cra-dependent color-shading correction | R11: https://datasheets.raspberrypi.com/camera/raspberry-pi-camera-guide.pdf | S11: S02 — Digital Negative (DNG) Specification 1.7.1.0 | T11: p. 115 (GainMap) | U11: https://helpx.adobe.com/content/dam/help/en/camera-raw/digital-negative/jcr_content/root/content/flex/items/position/position-par/download_section_733958301/download-1/DNG_Spec_1_7_1_0.pdf | V11: None | W11: Source/provenance review required before commercial release
A12: Not started | B12: 8 | C12: 1. RAW front end | D12: 1. Core ISP algorithms | E12: Core | F12: All configurations unless marked optional or sensor-specific | G12: P0 | H12: M | I12: Static sensor defect-map support | J12: Direct | K12: S02 — Digital Negative (DNG) Specification 1.7.1.0 | L12: p. 112 | M12: Store known bad coordinates and interpolate them with a FixBadPixelsList-style operation; combine the static map with adaptive DPC. | N12: Automated tests and representative RAW fixtures demonstrate static sensor defect-map support across declared modes, with documented tolerances and no regression in adjacent stages. | O12: Unit tests plus fixed RAW/image regression fixtures; record configuration, metrics and artifacts. | Q12: Python module, typed configuration and tests for static sensor defect-map support | R12: https://helpx.adobe.com/content/dam/help/en/camera-raw/digital-negative/jcr_content/root/content/flex/items/position/position-par/download_section_733958301/download-1/DNG_Spec_1_7_1_0.pdf | S12: S21 — EMVA Standard 1288 Release 3.0 | T12: pp. 25–27 | U12: https://www.emva.org/wp-content/uploads/EMVA1288-3.0.pdf | V12: None | W12: Source/provenance review required before commercial release
A13: Not started | B13: 9 | C13: 1. RAW front end | D13: 1. Core ISP algorithms | E13: Optional | F13: All configurations unless marked optional or sensor-specific | G13: P2 | H13: L | I13: PDAF masked-pixel correction, if applicable | J13: Sensor-specific | K13: S02 — Digital Negative (DNG) Specification 1.7.1.0 | L13: p. 112 | M13: Treat the sensor's PDAF/occluded sites as an explicit coordinate list and reconstruct them before demosaic; the exact map and grouping must come from the sensor vendor. | N13: Automated tests and representative RAW fixtures demonstrate pdaf masked-pixel correction, if applicable across declared modes, with documented tolerances and no regression in adjacent stages. | O13: Unit tests plus fixed RAW/image regression fixtures; record configuration, metrics and artifacts. | Q13: Python module, typed configuration and tests for pdaf masked-pixel correction, if applicable | R13: https://helpx.adobe.com/content/dam/help/en/camera-raw/digital-negative/jcr_content/root/content/flex/items/position/position-par/download_section_733958301/download-1/DNG_Spec_1_7_1_0.pdf | S13: S01 — Camera Algorithm and Tuning Guide | T13: pp. 45–47 (PDAF AF context) | U13: https://datasheets.raspberrypi.com/camera/raspberry-pi-camera-guide.pdf | V13: None | W13: Source/provenance review required before commercial release
A14: Not started | B14: 10 | C14: 1. RAW front end | D14: 1. Core ISP algorithms | E14: Core | F14: All configurations unless marked optional or sensor-specific | G14: P0 | H14: M | I14: Gain/exposure-dependent sensor noise model | J14: Direct | K14: S01 — Camera Algorithm and Tuning Guide | L14: p. 21 | M14: Calibrate slope/offset on reference captures, then adjust the profile by analog gain and sensor mode for every frame. | N14: Automated tests and representative RAW fixtures demonstrate gain/exposure-dependent sensor noise model across declared modes, with documented tolerances and no regression in adjacent stages. | O14: Unit tests plus fixed RAW/image regression fixtures; record configuration, metrics and artifacts. | Q14: Python module, typed configuration and tests for gain/exposure-dependent sensor noise model | R14: https://datasheets.raspberrypi.com/camera/raspberry-pi-camera-guide.pdf | S14: S21 — EMVA Standard 1288 Release 3.0 | T14: pp. 12–16 | U14: https://www.emva.org/wp-content/uploads/EMVA1288-3.0.pdf | V14: None | W14: Source/provenance review required before commercial release
A15: Not started | B15: 11 | C15: 2. Image statistics | D15: 1. Core ISP algorithms | E15: Core | F15: All configurations unless marked optional or sensor-specific | G15: P0 | H15: M | I15: Bayer/RGB histogram | J15: Direct | K15: S03 — V4L2 RKISP1 parameters and 3A statistics | L15: §2.13.9.2 | M15: Accumulate a bounded histogram from the Bayer frame or selected RGB/luma domain and publish it with the frame's statistics metadata. | N15: Automated tests and representative RAW fixtures demonstrate bayer/rgb histogram across declared modes, with documented tolerances and no regression in adjacent stages. | O15: Unit tests plus fixed RAW/image regression fixtures; record configuration, metrics and artifacts. | Q15: Python module, typed configuration and tests for bayer/rgb histogram | R15: https://docs.kernel.org/userspace-api/media/v4l/metafmt-rkisp1.html#:~:text=The%20statistics%20collected%20are%20Exposure | V15: None | W15: Source/provenance review required before commercial release
A16: Not started | B16: 12 | C16: 2. Image statistics | D16: 1. Core ISP algorithms | E16: Core | F16: All configurations unless marked optional or sensor-specific | G16: P0 | H16: M | I16: Regional exposure statistics | J16: Direct | K16: S03 — V4L2 RKISP1 parameters and 3A statistics | L16: rkisp1_cif_isp_window | M16: Define an exposure grid/window structure and emit sums or means per region so metering modes can apply their own weights. | N16: Automated tests and representative RAW fixtures demonstrate regional exposure statistics across declared modes, with documented tolerances and no regression in adjacent stages. | O16: Unit tests plus fixed RAW/image regression fixtures; record configuration, metrics and artifacts. | Q16: Python module, typed configuration and tests for regional exposure statistics | R16: https://docs.kernel.org/userspace-api/media/v4l/metafmt-rkisp1.html#:~:text=Measurements%20are%20calculated%20per%20window | S16: S01 — Camera Algorithm and Tuning Guide | T16: p. 32 | U16: https://datasheets.raspberrypi.com/camera/raspberry-pi-camera-guide.pdf | V16: None | W16: Source/provenance review required before commercial release
A17: Not started | B17: 13 | C17: 2. Image statistics | D17: 1. Core ISP algorithms | E17: Core | F17: All configurations unless marked optional or sensor-specific | G17: P0 | H17: M | I17: Highlight/saturation statistics | J17: Direct | K17: S01 — Camera Algorithm and Tuning Guide | L17: pp. 32–34 | M17: Track high histogram quantiles and channel saturation, then expose them to AE constraints so bright regions can be protected. | N17: Automated tests and representative RAW fixtures demonstrate highlight/saturation statistics across declared modes, with documented tolerances and no regression in adjacent stages. | O17: Unit tests plus fixed RAW/image regression fixtures; record configuration, metrics and artifacts. | Q17: Python module, typed configuration and tests for highlight/saturation statistics | R17: https://datasheets.raspberrypi.com/camera/raspberry-pi-camera-guide.pdf | V17: None | W17: Source/provenance review required before commercial release
A18: Not started | B18: 14 | C18: 2. Image statistics | D18: 1. Core ISP algorithms | E18: Core | F18: All configurations unless marked optional or sensor-specific | G18: P0 | H18: M | I18: AWB grid statistics | J18: Direct | K18: S03 — V4L2 RKISP1 parameters and 3A statistics | L18: rkisp1_cif_isp_awb_meas_config | M18: Compute neutral-candidate sums/counts over an AWB window or grid with luminance/chroma rejection thresholds and a configurable frame average. | N18: Automated tests and representative RAW fixtures demonstrate awb grid statistics across declared modes, with documented tolerances and no regression in adjacent stages. | O18: Unit tests plus fixed RAW/image regression fixtures; record configuration, metrics and artifacts. | Q18: Python module, typed configuration and tests for awb grid statistics | R18: https://docs.kernel.org/userspace-api/media/v4l/metafmt-rkisp1.html#:~:text=Configuration%20for%20the%20AWB%20statistics | S18: S01 — Camera Algorithm and Tuning Guide | T18: pp. 26–31 | U18: https://datasheets.raspberrypi.com/camera/raspberry-pi-camera-guide.pdf | V18: None | W18: Source/provenance review required before commercial release
A19: Not started | B19: 15 | C19: 2. Image statistics | D19: 1. Core ISP algorithms | E19: Core | F19: All configurations unless marked optional or sensor-specific | G19: P0 | H19: M | I19: Focus/sharpness statistics | J19: Direct | K19: S03 — V4L2 RKISP1 parameters and 3A statistics | L19: §2.13.9.2 (AF statistics) | M19: Publish contrast/phase focus measurements by window; keep the statistic independent of the lens controller. | N19: Automated tests and representative RAW fixtures demonstrate focus/sharpness statistics across declared modes, with documented tolerances and no regression in adjacent stages. | O19: Unit tests plus fixed RAW/image regression fixtures; record configuration, metrics and artifacts. | Q19: Python module, typed configuration and tests for focus/sharpness statistics | R19: https://docs.kernel.org/userspace-api/media/v4l/metafmt-rkisp1.html#:~:text=The%20statistics%20collected%20are%20Exposure | S19: S01 — Camera Algorithm and Tuning Guide | T19: pp. 45–47 | U19: https://datasheets.raspberrypi.com/camera/raspberry-pi-camera-guide.pdf | V19: None | W19: Source/provenance review required before commercial release
A20: Not started | B20: 16 | C20: 2. Image statistics | D20: 1. Core ISP algorithms | E20: Core | F20: All configurations unless marked optional or sensor-specific | G20: P0 | H20: M | I20: Scene brightness/lux estimate | J20: Direct | K20: S01 — Camera Algorithm and Tuning Guide | L20: pp. 20–21 | M20: Calibrate one reference lux/exposure/gain/Y sample and estimate current lux from the corresponding exposure, gain and image-statistic ratios. | N20: Automated tests and representative RAW fixtures demonstrate scene brightness/lux estimate across declared modes, with documented tolerances and no regression in adjacent stages. | O20: Unit tests plus fixed RAW/image regression fixtures; record configuration, metrics and artifacts. | Q20: Python module, typed configuration and tests for scene brightness/lux estimate | R20: https://datasheets.raspberrypi.com/camera/raspberry-pi-camera-guide.pdf | V20: None | W20: Source/provenance review required before commercial release
A21: Not started | B21: 17 | C21: 2. Image statistics | D21: 1. Core ISP algorithms | E21: Core | F21: All configurations unless marked optional or sensor-specific | G21: P0 | H21: M | I21: Frame-to-frame statistics history | J21: Direct | K21: S01 — Camera Algorithm and Tuning Guide | L21: pp. 12–13 | M21: Associate statistics with frame IDs, retain a bounded history, and use IIR/target filtering instead of reacting to a single noisy frame. | N21: Automated tests and representative RAW fixtures demonstrate frame-to-frame statistics history across declared modes, with documented tolerances and no regression in adjacent stages. | O21: Unit tests plus fixed RAW/image regression fixtures; record configuration, metrics and artifacts. | Q21: Python module, typed configuration and tests for frame-to-frame statistics history | R21: https://datasheets.raspberrypi.com/camera/raspberry-pi-camera-guide.pdf | V21: None | W21: Source/provenance review required before commercial release
A22: Not started | B22: 18 | C22: 3. Automatic control | D22: 1. Core ISP algorithms | E22: Core | F22: All configurations unless marked optional or sensor-specific | G22: P0 | H22: M | I22: Automatic exposure / gain control (AE/AGC) | J22: Direct | K22: S01 — Camera Algorithm and Tuning Guide | L22: pp. 31–37 | M22: Implement the controller around regional meters, histogram/channel constraints, exposure profiles and delayed sensor feedback. | N22: Automated tests and representative RAW fixtures demonstrate automatic exposure / gain control (ae/agc) across declared modes, with documented tolerances and no regression in adjacent stages. | O22: Unit tests plus fixed RAW/image regression fixtures; record configuration, metrics and artifacts. | Q22: Python module, typed configuration and tests for automatic exposure / gain control (ae/agc) | R22: https://datasheets.raspberrypi.com/camera/raspberry-pi-camera-guide.pdf | V22: None | W22: Source/provenance review required before commercial release
A23: Not started | B23: 19 | C23: 3. Automatic control | D23: 1. Core ISP algorithms | E23: Core | F23: All configurations unless marked optional or sensor-specific | G23: P0 | H23: M | I23: Exposure metering modes and user regions | J23: Direct | K23: S01 — Camera Algorithm and Tuning Guide | L23: pp. 32, 35–36 | M23: Provide center-weighted/matrix/spot weight tables and user rectangles; reduce all modes to explicit regional weights. | N23: Automated tests and representative RAW fixtures demonstrate exposure metering modes and user regions across declared modes, with documented tolerances and no regression in adjacent stages. | O23: Unit tests plus fixed RAW/image regression fixtures; record configuration, metrics and artifacts. | Q23: Python module, typed configuration and tests for exposure metering modes and user regions | R23: https://datasheets.raspberrypi.com/camera/raspberry-pi-camera-guide.pdf | S23: S03 — V4L2 RKISP1 parameters and 3A statistics | T23: rkisp1_cif_isp_window | U23: https://docs.kernel.org/userspace-api/media/v4l/metafmt-rkisp1.html#:~:text=Measurements%20are%20calculated%20per%20window | V23: None | W23: Source/provenance review required before commercial release
A24: Not started | B24: 20 | C24: 3. Automatic control | D24: 1. Core ISP algorithms | E24: Core | F24: All configurations unless marked optional or sensor-specific | G24: P0 | H24: M | I24: Highlight-preserving exposure | J24: Direct | K24: S01 — Camera Algorithm and Tuning Guide | L24: pp. 32–34 | M24: Add histogram quantile and per-channel clipping constraints that cap exposure even when the mean target requests more gain. | N24: Automated tests and representative RAW fixtures demonstrate highlight-preserving exposure across declared modes, with documented tolerances and no regression in adjacent stages. | O24: Unit tests plus fixed RAW/image regression fixtures; record configuration, metrics and artifacts. | Q24: Python module, typed configuration and tests for highlight-preserving exposure | R24: https://datasheets.raspberrypi.com/camera/raspberry-pi-camera-guide.pdf | V24: None | W24: Source/provenance review required before commercial release
A25: Not started | B25: 21 | C25: 3. Automatic control | D25: 1. Core ISP algorithms | E25: Core | F25: All configurations unless marked optional or sensor-specific | G25: P0 | H25: M | I25: Exposure convergence and stability control | J25: Direct | K25: S01 — Camera Algorithm and Tuning Guide | L25: pp. 35–37; p. 13 | M25: Define convergence tolerances, startup behavior and filtered target updates; limit shutter/gain step size per frame. | N25: Automated tests and representative RAW fixtures demonstrate exposure convergence and stability control across declared modes, with documented tolerances and no regression in adjacent stages. | O25: Unit tests plus fixed RAW/image regression fixtures; record configuration, metrics and artifacts. | Q25: Python module, typed configuration and tests for exposure convergence and stability control | R25: https://datasheets.raspberrypi.com/camera/raspberry-pi-camera-guide.pdf | V25: None | W25: Source/provenance review required before commercial release
A26: Not started | B26: 22 | C26: 3. Automatic control | D26: 1. Core ISP algorithms | E26: Core | F26: All configurations unless marked optional or sensor-specific | G26: P0 | H26: M | I26: 50/60 Hz anti-flicker | J26: Direct | K26: S01 — Camera Algorithm and Tuning Guide | L26: p. 35 | M26: Quantize exposure time to a configurable flicker period through the AE controller while allowing an explicit disable/manual override. | N26: Automated tests and representative RAW fixtures demonstrate 50/60 hz anti-flicker across declared modes, with documented tolerances and no regression in adjacent stages. | O26: Unit tests plus fixed RAW/image regression fixtures; record configuration, metrics and artifacts. | Q26: Python module, typed configuration and tests for 50/60 hz anti-flicker | R26: https://datasheets.raspberrypi.com/camera/raspberry-pi-camera-guide.pdf | V26: None | W26: Source/provenance review required before commercial release
A27: Not started | B27: 23 | C27: 3. Automatic control | D27: 1. Core ISP algorithms | E27: Core | F27: All configurations unless marked optional or sensor-specific | G27: P0 | H27: M | I27: Automatic white-balance estimation | J27: Direct | K27: S01 — Camera Algorithm and Tuning Guide | L27: pp. 26–31 | M27: Estimate red/blue gains from feasible neutral candidates with a Bayesian illuminant prior/likelihood; keep estimation separate from gain application. | N27: Automated tests and representative RAW fixtures demonstrate automatic white-balance estimation across declared modes, with documented tolerances and no regression in adjacent stages. | O27: Unit tests plus fixed RAW/image regression fixtures; record configuration, metrics and artifacts. | Q27: Python module, typed configuration and tests for automatic white-balance estimation | R27: https://datasheets.raspberrypi.com/camera/raspberry-pi-camera-guide.pdf | V27: None | W27: Source/provenance review required before commercial release
A28: Not started | B28: 24 | C28: 3. Automatic control | D28: 1. Core ISP algorithms | E28: Core | F28: All configurations unless marked optional or sensor-specific | G28: P0 | H28: M | I28: Illuminant and correlated-color-temperature estimation | J28: Direct | K28: S01 — Camera Algorithm and Tuning Guide | L28: pp. 26–31 | M28: Return both channel gains and an illuminant/CCT estimate so CCM and lens shading can interpolate consistently. | N28: Automated tests and representative RAW fixtures demonstrate illuminant and correlated-color-temperature estimation across declared modes, with documented tolerances and no regression in adjacent stages. | O28: Unit tests plus fixed RAW/image regression fixtures; record configuration, metrics and artifacts. | Q28: Python module, typed configuration and tests for illuminant and correlated-color-temperature estimation | R28: https://datasheets.raspberrypi.com/camera/raspberry-pi-camera-guide.pdf | V28: None | W28: Source/provenance review required before commercial release
A29: Not started | B29: 25 | C29: 3. Automatic control | D29: 1. Core ISP algorithms | E29: Core | F29: All configurations unless marked optional or sensor-specific | G29: P0 | H29: M | I29: AWB convergence and temporal smoothing | J29: Direct | K29: S01 — Camera Algorithm and Tuning Guide | L29: pp. 29–31; p. 13 | M29: Filter gains/CCT toward asynchronous AWB targets, expose convergence state, and use faster startup than steady-state smoothing. | N29: Automated tests and representative RAW fixtures demonstrate awb convergence and temporal smoothing across declared modes, with documented tolerances and no regression in adjacent stages. | O29: Unit tests plus fixed RAW/image regression fixtures; record configuration, metrics and artifacts. | Q29: Python module, typed configuration and tests for awb convergence and temporal smoothing | R29: https://datasheets.raspberrypi.com/camera/raspberry-pi-camera-guide.pdf | V29: None | W29: Source/provenance review required before commercial release
A30: Not started | B30: 26 | C30: 3. Automatic control | D30: 1. Core ISP algorithms | E30: Optional | F30: All configurations unless marked optional or sensor-specific | G30: P2 | H30: L | I30: Autofocus controller | J30: Direct | K30: S01 — Camera Algorithm and Tuning Guide | L30: pp. 45–47 | M30: Support manual, one-shot and continuous modes; provide contrast/phase feedback, windows, scan steps, slew limits and termination criteria. | N30: Automated tests and representative RAW fixtures demonstrate autofocus controller across declared modes, with documented tolerances and no regression in adjacent stages. | O30: Unit tests plus fixed RAW/image regression fixtures; record configuration, metrics and artifacts. | Q30: Python module, typed configuration and tests for autofocus controller | R30: https://datasheets.raspberrypi.com/camera/raspberry-pi-camera-guide.pdf | V30: None | W30: Source/provenance review required before commercial release
A31: Not started | B31: 27 | C31: 3. Automatic control | D31: 1. Core ISP algorithms | E31: Core | F31: All configurations unless marked optional or sensor-specific | G31: P0 | H31: M | I31: Manual AE/AWB/AF overrides and locks | J31: Direct | K31: S01 — Camera Algorithm and Tuning Guide | L31: pp. 29–31, 35, 45–47 | M31: Expose manual shutter/gain, WB gains/mode and lens position; report the frame on which each requested value takes effect. | N31: Automated tests and representative RAW fixtures demonstrate manual ae/awb/af overrides and locks across declared modes, with documented tolerances and no regression in adjacent stages. | O31: Unit tests plus fixed RAW/image regression fixtures; record configuration, metrics and artifacts. | Q31: Python module, typed configuration and tests for manual ae/awb/af overrides and locks | R31: https://datasheets.raspberrypi.com/camera/raspberry-pi-camera-guide.pdf | V31: None | W31: Source/provenance review required before commercial release
A32: Not started | B32: 28 | C32: 4. HDR and dynamic range | D32: 1. Core ISP algorithms | E32: Advanced | F32: All configurations unless marked optional or sensor-specific | G32: P1 | H32: L | I32: Multi-exposure HDR ingestion | J32: Direct | K32: S05 — High Dynamic Range Imaging | L32: HDR image sequence input | M32: Accept exposure-bracketed frames plus exposure times and frame identity; validate consistent dimensions, CFA and black/white calibration. | N32: Automated tests and representative RAW fixtures demonstrate multi-exposure hdr ingestion across declared modes, with documented tolerances and no regression in adjacent stages. | O32: Unit tests plus fixed RAW/image regression fixtures; record configuration, metrics and artifacts. | Q32: Python module, typed configuration and tests for multi-exposure hdr ingestion | R32: https://docs.opencv.org/4.x/d2/df0/tutorial_py_hdr.html#:~:text=HDR%20images%20encompass%20the%20information | S32: S01 — Camera Algorithm and Tuning Guide | T32: pp. 48–50 | U32: https://datasheets.raspberrypi.com/camera/raspberry-pi-camera-guide.pdf | V32: None | W32: Source/provenance review required before commercial release
A33: Not started | B33: 29 | C33: 4. HDR and dynamic range | D33: 1. Core ISP algorithms | E33: Advanced | F33: All configurations unless marked optional or sensor-specific | G33: P1 | H33: L | I33: HDR exposure normalization | J33: Direct | K33: S02 — Digital Negative (DNG) Specification 1.7.1.0 | L33: p. 88 (ImageSequenceInfo) | M33: Normalize each frame to radiance using exposure time/gain and calibrated response before alignment or merge. | N33: Automated tests and representative RAW fixtures demonstrate hdr exposure normalization across declared modes, with documented tolerances and no regression in adjacent stages. | O33: Unit tests plus fixed RAW/image regression fixtures; record configuration, metrics and artifacts. | Q33: Python module, typed configuration and tests for hdr exposure normalization | R33: https://helpx.adobe.com/content/dam/help/en/camera-raw/digital-negative/jcr_content/root/content/flex/items/position/position-par/download_section_733958301/download-1/DNG_Spec_1_7_1_0.pdf | S33: S05 — High Dynamic Range Imaging | T33: Camera response calibration / MergeDebevec | U33: https://docs.opencv.org/4.x/d2/df0/tutorial_py_hdr.html | V33: None | W33: Source/provenance review required before commercial release
A34: Not started | B34: 30 | C34: 4. HDR and dynamic range | D34: 1. Core ISP algorithms | E34: Advanced | F34: All configurations unless marked optional or sensor-specific | G34: P1 | H34: L | I34: Exposure alignment | J34: Direct | K34: S06 — Robust Patch-Based HDR Reconstruction of Dynamic Scenes | L34: pp. 3–6 | M34: Align exposures in a radiometrically comparable domain; use multi-scale correspondence and retain validity/occlusion masks. | N34: Automated tests and representative RAW fixtures demonstrate exposure alignment across declared modes, with documented tolerances and no regression in adjacent stages. | O34: Unit tests plus fixed RAW/image regression fixtures; record configuration, metrics and artifacts. | Q34: Python module, typed configuration and tests for exposure alignment | R34: https://people.engr.tamu.edu/nimak/Data/SIGASIA12_HDR_PatchBasedReconstruction.pdf | S34: S10 — Optical Flow | T34: Farnebäck or pyramidal Lucas–Kanade | U34: https://docs.opencv.org/4.x/d4/dee/tutorial_optical_flow.html | V34: None | W34: Source/provenance review required before commercial release
A35: Not started | B35: 31 | C35: 4. HDR and dynamic range | D35: 1. Core ISP algorithms | E35: Advanced | F35: All configurations unless marked optional or sensor-specific | G35: P1 | H35: L | I35: HDR merge | J35: Direct | K35: S05 — High Dynamic Range Imaging | L35: Debevec merge and Mertens exposure fusion | M35: Implement both radiance-map merge and exposure fusion; weight away from saturated/underexposed samples and preserve float output. | N35: Automated tests and representative RAW fixtures demonstrate hdr merge across declared modes, with documented tolerances and no regression in adjacent stages. | O35: Unit tests plus fixed RAW/image regression fixtures; record configuration, metrics and artifacts. | Q35: Python module, typed configuration and tests for hdr merge | R35: https://docs.opencv.org/4.x/d2/df0/tutorial_py_hdr.html#:~:text=Merge%20images%20into%20an%20HDR%20linear%20image | S35: S02 — Digital Negative (DNG) Specification 1.7.1.0 | T35: p. 88 | U35: https://helpx.adobe.com/content/dam/help/en/camera-raw/digital-negative/jcr_content/root/content/flex/items/position/position-par/download_section_733958301/download-1/DNG_Spec_1_7_1_0.pdf | V35: None | W35: Source/provenance review required before commercial release
A36: Not started | B36: 32 | C36: 4. HDR and dynamic range | D36: 1. Core ISP algorithms | E36: Advanced | F36: All configurations unless marked optional or sensor-specific | G36: P1 | H36: L | I36: Motion and ghost detection | J36: Direct | K36: S06 — Robust Patch-Based HDR Reconstruction of Dynamic Scenes | L36: pp. 2–7 | M36: Detect inconsistent/moving regions, maintain correspondence confidence, and either jointly reconstruct or reject unreliable samples during merge. | N36: Automated tests and representative RAW fixtures demonstrate motion and ghost detection across declared modes, with documented tolerances and no regression in adjacent stages. | O36: Unit tests plus fixed RAW/image regression fixtures; record configuration, metrics and artifacts. | Q36: Python module, typed configuration and tests for motion and ghost detection | R36: https://people.engr.tamu.edu/nimak/Data/SIGASIA12_HDR_PatchBasedReconstruction.pdf | V36: None | W36: Source/provenance review required before commercial release
A37: Not started | B37: 33 | C37: 4. HDR and dynamic range | D37: 1. Core ISP algorithms | E37: Core | F37: All configurations unless marked optional or sensor-specific | G37: P0 | H37: M | I37: Global tone mapping | J37: Direct | K37: S07 — Photographic Tone Reproduction for Digital Images | L37: p. 3, §3.1 | M37: Use log-average luminance to set key/exposure and apply the photographic compression curve in linear luminance. | N37: Automated tests and representative RAW fixtures demonstrate global tone mapping across declared modes, with documented tolerances and no regression in adjacent stages. | O37: Unit tests plus fixed RAW/image regression fixtures; record configuration, metrics and artifacts. | Q37: Python module, typed configuration and tests for global tone mapping | R37: https://web.tecgraf.puc-rio.br/~scuri/inf1378/pub/reinhard.pdf | V37: None | W37: Source/provenance review required before commercial release
A38: Not started | B38: 34 | C38: 4. HDR and dynamic range | D38: 1. Core ISP algorithms | E38: Advanced | F38: All configurations unless marked optional or sensor-specific | G38: P1 | H38: L | I38: Local/adaptive tone mapping | J38: Direct | K38: S07 — Photographic Tone Reproduction for Digital Images | L38: pp. 3–5, §3.2 | M38: Select a local luminance scale with multi-scale Gaussian responses, then use it in the compression denominator while checking for halos. | N38: Automated tests and representative RAW fixtures demonstrate local/adaptive tone mapping across declared modes, with documented tolerances and no regression in adjacent stages. | O38: Unit tests plus fixed RAW/image regression fixtures; record configuration, metrics and artifacts. | Q38: Python module, typed configuration and tests for local/adaptive tone mapping | R38: https://web.tecgraf.puc-rio.br/~scuri/inf1378/pub/reinhard.pdf | V38: None | W38: Source/provenance review required before commercial release
A39: Not started | B39: 35 | C39: 4. HDR and dynamic range | D39: 1. Core ISP algorithms | E39: Core | F39: All configurations unless marked optional or sensor-specific | G39: P0 | H39: M | I39: Highlight roll-off | J39: Direct | K39: S07 — Photographic Tone Reproduction for Digital Images | L39: p. 3, equations 3–4 | M39: Use the white-point parameter and smooth rational compression rather than hard clipping; tune the smallest luminance that maps to output white. | N39: Automated tests and representative RAW fixtures demonstrate highlight roll-off across declared modes, with documented tolerances and no regression in adjacent stages. | O39: Unit tests plus fixed RAW/image regression fixtures; record configuration, metrics and artifacts. | Q39: Python module, typed configuration and tests for highlight roll-off | R39: https://web.tecgraf.puc-rio.br/~scuri/inf1378/pub/reinhard.pdf | V39: None | W39: Source/provenance review required before commercial release
A40: Not started | B40: 36 | C40: 4. HDR and dynamic range | D40: 1. Core ISP algorithms | E40: Core | F40: All configurations unless marked optional or sensor-specific | G40: P0 | H40: M | I40: Shadow enhancement | J40: Direct | K40: S07 — Photographic Tone Reproduction for Digital Images | L40: pp. 3–5 | M40: Lift low luminance through key scaling/local adaptation while bounding noise amplification with the per-frame noise profile. | N40: Automated tests and representative RAW fixtures demonstrate shadow enhancement across declared modes, with documented tolerances and no regression in adjacent stages. | O40: Unit tests plus fixed RAW/image regression fixtures; record configuration, metrics and artifacts. | Q40: Python module, typed configuration and tests for shadow enhancement | R40: https://web.tecgraf.puc-rio.br/~scuri/inf1378/pub/reinhard.pdf | S40: S01 — Camera Algorithm and Tuning Guide | T40: pp. 41–43 | U40: https://datasheets.raspberrypi.com/camera/raspberry-pi-camera-guide.pdf | V40: None | W40: Source/provenance review required before commercial release
...

Sheet Coverage Summary
A1: Coverage Summary
A2: Scope is the primary planning pivot. Completion excludes Status = N/A. Formulas use ordinary bounded ranges through row 300 so newly populated reserved rows are counted without relying on dynamic arrays.
A3: Total items | B3: =COUNTIF(Checklist!$B$4:$B$300,"<>") -> 151 | C3: Applicable | D3: =B3-COUNTIF(Checklist!$A$4:$A$300,"N/A") -> 151 | E3: Done | F3: =COUNTIF(Checklist!$A$4:$A$300,"Done") -> 0 | G3: % complete | H3: =IF(D3=0,0,F3/D3) -> 0 | I3: N/A | J3: =COUNTIF(Checklist!$A$4:$A$300,"N/A") -> 0
A4: Not started | B4: =COUNTIF(Checklist!$A$4:$A$300,"Not started") -> 151 | C4: In progress | D4: =COUNTIF(Checklist!$A$4:$A$300,"In progress") -> 0 | E4: With primary source | F4: =COUNTIFS(Checklist!$B$4:$B$300,"<>",Checklist!$R$4:$R$300,"<>") -> 151 | G4: Direct | H4: =COUNTIF(Checklist!$J$4:$J$300,"Direct") -> 129 | I4: Sensor-specific | J4: =COUNTIF(Checklist!$J$4:$J$300,"Sensor-specific") -> 8
A5: Unassigned | B5: =COUNTIFS(Checklist!$B$4:$B$300,"<>",Checklist!$X$4:$X$300,"") -> 151 | C5: Required artifacts | D5: =COUNTIFS(Checklist!$B$4:$B$300,"<>",Checklist!$V$4:$V$300,"<>None") -> 19 | E5: IP/legal review rows | F5: =COUNTIFS(Checklist!$B$4:$B$300,"<>",Checklist!$W$4:$W$300,"*review*") -> 149
A7: Scope | B7: Items | C7: Done | D7: N/A | E7: Applicable | F7: % complete | G7: Direct | H7: Sensor-specific | I7: Unassigned
A8: 1. Core ISP algorithms | B8: =COUNTIF(Checklist!$D$4:$D$300,A8) -> 93 | C8: =COUNTIFS(Checklist!$D$4:$D$300,A8,Checklist!$A$4:$A$300,"Done") -> 0 | D8: =COUNTIFS(Checklist!$D$4:$D$300,A8,Checklist!$A$4:$A$300,"N/A") -> 0 | E8: =B8-D8 -> 93 | F8: =IF(E8=0,0,C8/E8) -> 0 | G8: =COUNTIFS(Checklist!$D$4:$D$300,A8,Checklist!$J$4:$J$300,"Direct") -> 84 | H8: =COUNTIFS(Checklist!$D$4:$D$300,A8,Checklist!$J$4:$J$300,"Sensor-specific") -> 1 | I8: =COUNTIFS(Checklist!$D$4:$D$300,A8,Checklist!$B$4:$B$300,"<>",Checklist!$X$4:$X$300,"") -> 93
A9: 2. Sensor and lens integration | B9: =COUNTIF(Checklist!$D$4:$D$300,A9) -> 12 | C9: =COUNTIFS(Checklist!$D$4:$D$300,A9,Checklist!$A$4:$A$300,"Done") -> 0 | D9: =COUNTIFS(Checklist!$D$4:$D$300,A9,Checklist!$A$4:$A$300,"N/A") -> 0 | E9: =B9-D9 -> 12 | F9: =IF(E9=0,0,C9/E9) -> 0 | G9: =COUNTIFS(Checklist!$D$4:$D$300,A9,Checklist!$J$4:$J$300,"Direct") -> 3 | H9: =COUNTIFS(Checklist!$D$4:$D$300,A9,Checklist!$J$4:$J$300,"Sensor-specific") -> 7 | I9: =COUNTIFS(Checklist!$D$4:$D$300,A9,Checklist!$B$4:$B$300,"<>",Checklist!$X$4:$X$300,"") -> 12
A10: 3. Camera product integration | B10: =COUNTIF(Checklist!$D$4:$D$300,A10) -> 14 | C10: =COUNTIFS(Checklist!$D$4:$D$300,A10,Checklist!$A$4:$A$300,"Done") -> 0 | D10: =COUNTIFS(Checklist!$D$4:$D$300,A10,Checklist!$A$4:$A$300,"N/A") -> 0 | E10: =B10-D10 -> 14 | F10: =IF(E10=0,0,C10/E10) -> 0 | G10: =COUNTIFS(Checklist!$D$4:$D$300,A10,Checklist!$J$4:$J$300,"Direct") -> 12 | H10: =COUNTIFS(Checklist!$D$4:$D$300,A10,Checklist!$J$4:$J$300,"Sensor-specific") -> 0 | I10: =COUNTIFS(Checklist!$D$4:$D$300,A10,Checklist!$B$4:$B$300,"<>",Checklist!$X$4:$X$300,"") -> 14
A11: 4. Drone/computational-imaging extensions | B11: =COUNTIF(Checklist!$D$4:$D$300,A11) -> 12 | C11: =COUNTIFS(Checklist!$D$4:$D$300,A11,Checklist!$A$4:$A$300,"Done") -> 0 | D11: =COUNTIFS(Checklist!$D$4:$D$300,A11,Checklist!$A$4:$A$300,"N/A") -> 0 | E11: =B11-D11 -> 12 | F11: =IF(E11=0,0,C11/E11) -> 0 | G11: =COUNTIFS(Checklist!$D$4:$D$300,A11,Checklist!$J$4:$J$300,"Direct") -> 10 | H11: =COUNTIFS(Checklist!$D$4:$D$300,A11,Checklist!$J$4:$J$300,"Sensor-specific") -> 0 | I11: =COUNTIFS(Checklist!$D$4:$D$300,A11,Checklist!$B$4:$B$300,"<>",Checklist!$X$4:$X$300,"") -> 12
A12: 5. Engineering, validation, performance, licensing, release readiness | B12: =COUNTIF(Checklist!$D$4:$D$300,A12) -> 20 | C12: =COUNTIFS(Checklist!$D$4:$D$300,A12,Checklist!$A$4:$A$300,"Done") -> 0 | D12: =COUNTIFS(Checklist!$D$4:$D$300,A12,Checklist!$A$4:$A$300,"N/A") -> 0 | E12: =B12-D12 -> 20 | F12: =IF(E12=0,0,C12/E12) -> 0 | G12: =COUNTIFS(Checklist!$D$4:$D$300,A12,Checklist!$J$4:$J$300,"Direct") -> 20 | H12: =COUNTIFS(Checklist!$D$4:$D$300,A12,Checklist!$J$4:$J$300,"Sensor-specific") -> 0 | I12: =COUNTIFS(Checklist!$D$4:$D$300,A12,Checklist!$B$4:$B$300,"<>",Checklist!$X$4:$X$300,"") -> 20
A15: Category | B15: Items | C15: Done | D15: N/A | E15: Applicable | F15: % complete | G15: Direct | H15: Sensor-specific | I15: Unassigned
A16: 1. RAW front end | B16: =COUNTIF(Checklist!$C$4:$C$300,A16) -> 13 | C16: =COUNTIFS(Checklist!$C$4:$C$300,A16,Checklist!$A$4:$A$300,"Done") -> 0 | D16: =COUNTIFS(Checklist!$C$4:$C$300,A16,Checklist!$A$4:$A$300,"N/A") -> 0 | E16: =B16-D16 -> 13 | F16: =IF(E16=0,0,C16/E16) -> 0 | G16: =COUNTIFS(Checklist!$C$4:$C$300,A16,Checklist!$J$4:$J$300,"Direct") -> 12 | H16: =COUNTIFS(Checklist!$C$4:$C$300,A16,Checklist!$J$4:$J$300,"Sensor-specific") -> 1 | I16: =COUNTIFS(Checklist!$C$4:$C$300,A16,Checklist!$B$4:$B$300,"<>",Checklist!$X$4:$X$300,"") -> 13
A17: 2. Image statistics | B17: =COUNTIF(Checklist!$C$4:$C$300,A17) -> 9 | C17: =COUNTIFS(Checklist!$C$4:$C$300,A17,Checklist!$A$4:$A$300,"Done") -> 0 | D17: =COUNTIFS(Checklist!$C$4:$C$300,A17,Checklist!$A$4:$A$300,"N/A") -> 0 | E17: =B17-D17 -> 9 | F17: =IF(E17=0,0,C17/E17) -> 0 | G17: =COUNTIFS(Checklist!$C$4:$C$300,A17,Checklist!$J$4:$J$300,"Direct") -> 7 | H17: =COUNTIFS(Checklist!$C$4:$C$300,A17,Checklist!$J$4:$J$300,"Sensor-specific") -> 1 | I17: =COUNTIFS(Checklist!$C$4:$C$300,A17,Checklist!$B$4:$B$300,"<>",Checklist!$X$4:$X$300,"") -> 9
A18: 3. Automatic control | B18: =COUNTIF(Checklist!$C$4:$C$300,A18) -> 13 | C18: =COUNTIFS(Checklist!$C$4:$C$300,A18,Checklist!$A$4:$A$300,"Done") -> 0 | D18: =COUNTIFS(Checklist!$C$4:$C$300,A18,Checklist!$A$4:$A$300,"N/A") -> 0 | E18: =B18-D18 -> 13 | F18: =IF(E18=0,0,C18/E18) -> 0 | G18: =COUNTIFS(Checklist!$C$4:$C$300,A18,Checklist!$J$4:$J$300,"Direct") -> 10 | H18: =COUNTIFS(Checklist!$C$4:$C$300,A18,Checklist!$J$4:$J$300,"Sensor-specific") -> 1 | I18: =COUNTIFS(Checklist!$C$4:$C$300,A18,Checklist!$B$4:$B$300,"<>",Checklist!$X$4:$X$300,"") -> 13
A19: 4. HDR and dynamic range | B19: =COUNTIF(Checklist!$C$4:$C$300,A19) -> 13 | C19: =COUNTIFS(Checklist!$C$4:$C$300,A19,Checklist!$A$4:$A$300,"Done") -> 0 | D19: =COUNTIFS(Checklist!$C$4:$C$300,A19,Checklist!$A$4:$A$300,"N/A") -> 0 | E19: =B19-D19 -> 13 | F19: =IF(E19=0,0,C19/E19) -> 0 | G19: =COUNTIFS(Checklist!$C$4:$C$300,A19,Checklist!$J$4:$J$300,"Direct") -> 10 | H19: =COUNTIFS(Checklist!$C$4:$C$300,A19,Checklist!$J$4:$J$300,"Sensor-specific") -> 3 | I19: =COUNTIFS(Checklist!$C$4:$C$300,A19,Checklist!$B$4:$B$300,"<>",Checklist!$X$4:$X$300,"") -> 13
A20: 5. Noise reduction | B20: =COUNTIF(Checklist!$C$4:$C$300,A20) -> 9 | C20: =COUNTIFS(Checklist!$C$4:$C$300,A20,Checklist!$A$4:$A$300,"Done") -> 0 | D20: =COUNTIFS(Checklist!$C$4:$C$300,A20,Checklist!$A$4:$A$300,"N/A") -> 0 | E20: =B20-D20 -> 9 | F20: =IF(E20=0,0,C20/E20) -> 0 | G20: =COUNTIFS(Checklist!$C$4:$C$300,A20,Checklist!$J$4:$J$300,"Direct") -> 8 | H20: =COUNTIFS(Checklist!$C$4:$C$300,A20,Checklist!$J$4:$J$300,"Sensor-specific") -> 0 | I20: =COUNTIFS(Checklist!$C$4:$C$300,A20,Checklist!$B$4:$B$300,"<>",Checklist!$X$4:$X$300,"") -> 9
A21: 6. Demosaic and artifacts | B21: =COUNTIF(Checklist!$C$4:$C$300,A21) -> 8 | C21: =COUNTIFS(Checklist!$C$4:$C$300,A21,Checklist!$A$4:$A$300,"Done") -> 0 | D21: =COUNTIFS(Checklist!$C$4:$C$300,A21,Checklist!$A$4:$A$300,"N/A") -> 0 | E21: =B21-D21 -> 8 | F21: =IF(E21=0,0,C21/E21) -> 0 | G21: =COUNTIFS(Checklist!$C$4:$C$300,A21,Checklist!$J$4:$J$300,"Direct") -> 5 | H21: =COUNTIFS(Checklist!$C$4:$C$300,A21,Checklist!$J$4:$J$300,"Sensor-specific") -> 2 | I21: =COUNTIFS(Checklist!$C$4:$C$300,A21,Checklist!$B$4:$B$300,"<>",Checklist!$X$4:$X$300,"") -> 8
A22: 7. Color | B22: =COUNTIF(Checklist!$C$4:$C$300,A22) -> 9 | C22: =COUNTIFS(Checklist!$C$4:$C$300,A22,Checklist!$A$4:$A$300,"Done") -> 0 | D22: =COUNTIFS(Checklist!$C$4:$C$300,A22,Checklist!$A$4:$A$300,"N/A") -> 0 | E22: =B22-D22 -> 9 | F22: =IF(E22=0,0,C22/E22) -> 0 | G22: =COUNTIFS(Checklist!$C$4:$C$300,A22,Checklist!$J$4:$J$300,"Direct") -> 8 | H22: =COUNTIFS(Checklist!$C$4:$C$300,A22,Checklist!$J$4:$J$300,"Sensor-specific") -> 0 | I22: =COUNTIFS(Checklist!$C$4:$C$300,A22,Checklist!$B$4:$B$300,"<>",Checklist!$X$4:$X$300,"") -> 9
A23: 8. Detail and appearance | B23: =COUNTIF(Checklist!$C$4:$C$300,A23) -> 9 | C23: =COUNTIFS(Checklist!$C$4:$C$300,A23,Checklist!$A$4:$A$300,"Done") -> 0 | D23: =COUNTIFS(Checklist!$C$4:$C$300,A23,Checklist!$A$4:$A$300,"N/A") -> 0 | E23: =B23-D23 -> 9 | F23: =IF(E23=0,0,C23/E23) -> 0 | G23: =COUNTIFS(Checklist!$C$4:$C$300,A23,Checklist!$J$4:$J$300,"Direct") -> 7 | H23: =COUNTIFS(Checklist!$C$4:$C$300,A23,Checklist!$J$4:$J$300,"Sensor-specific") -> 0 | I23: =COUNTIFS(Checklist!$C$4:$C$300,A23,Checklist!$B$4:$B$300,"<>",Checklist!$X$4:$X$300,"") -> 9
A24: 9. Geometry and output | B24: =COUNTIF(Checklist!$C$4:$C$300,A24) -> 12 | C24: =COUNTIFS(Checklist!$C$4:$C$300,A24,Checklist!$A$4:$A$300,"Done") -> 0 | D24: =COUNTIFS(Checklist!$C$4:$C$300,A24,Checklist!$A$4:$A$300,"N/A") -> 0 | E24: =B24-D24 -> 12 | F24: =IF(E24=0,0,C24/E24) -> 0 | G24: =COUNTIFS(Checklist!$C$4:$C$300,A24,Checklist!$J$4:$J$300,"Direct") -> 11 | H24: =COUNTIFS(Checklist!$C$4:$C$300,A24,Checklist!$J$4:$J$300,"Sensor-specific") -> 0 | I24: =COUNTIFS(Checklist!$C$4:$C$300,A24,Checklist!$B$4:$B$300,"<>",Checklist!$X$4:$X$300,"") -> 12
A25: 10. Drone-specific | B25: =COUNTIF(Checklist!$C$4:$C$300,A25) -> 11 | C25: =COUNTIFS(Checklist!$C$4:$C$300,A25,Checklist!$A$4:$A$300,"Done") -> 0 | D25: =COUNTIFS(Checklist!$C$4:$C$300,A25,Checklist!$A$4:$A$300,"N/A") -> 0 | E25: =B25-D25 -> 11 | F25: =IF(E25=0,0,C25/E25) -> 0 | G25: =COUNTIFS(Checklist!$C$4:$C$300,A25,Checklist!$J$4:$J$300,"Direct") -> 9 | H25: =COUNTIFS(Checklist!$C$4:$C$300,A25,Checklist!$J$4:$J$300,"Sensor-specific") -> 0 | I25: =COUNTIFS(Checklist!$C$4:$C$300,A25,Checklist!$B$4:$B$300,"<>",Checklist!$X$4:$X$300,"") -> 11
A26: 11. Tuning and calibration | B26: =COUNTIF(Checklist!$C$4:$C$300,A26) -> 19 | C26: =COUNTIFS(Checklist!$C$4:$C$300,A26,Checklist!$A$4:$A$300,"Done") -> 0 | D26: =COUNTIFS(Checklist!$C$4:$C$300,A26,Checklist!$A$4:$A$300,"N/A") -> 0 | E26: =B26-D26 -> 19 | F26: =IF(E26=0,0,C26/E26) -> 0 | G26: =COUNTIFS(Checklist!$C$4:$C$300,A26,Checklist!$J$4:$J$300,"Direct") -> 17 | H26: =COUNTIFS(Checklist!$C$4:$C$300,A26,Checklist!$J$4:$J$300,"Sensor-specific") -> 0 | I26: =COUNTIFS(Checklist!$C$4:$C$300,A26,Checklist!$B$4:$B$300,"<>",Checklist!$X$4:$X$300,"") -> 19
A27: 12. Package/control architecture | B27: =COUNTIF(Checklist!$C$4:$C$300,A27) -> 20 | C27: =COUNTIFS(Checklist!$C$4:$C$300,A27,Checklist!$A$4:$A$300,"Done") -> 0 | D27: =COUNTIFS(Checklist!$C$4:$C$300,A27,Checklist!$A$4:$A$300,"N/A") -> 0 | E27: =B27-D27 -> 20 | F27: =IF(E27=0,0,C27/E27) -> 0 | G27: =COUNTIFS(Checklist!$C$4:$C$300,A27,Checklist!$J$4:$J$300,"Direct") -> 19 | H27: =COUNTIFS(Checklist!$C$4:$C$300,A27,Checklist!$J$4:$J$300,"Sensor-specific") -> 0 | I27: =COUNTIFS(Checklist!$C$4:$C$300,A27,Checklist!$B$4:$B$300,"<>",Checklist!$X$4:$X$300,"") -> 20
A28: 13. Specific openISP fixes | B28: =COUNTIF(Checklist!$C$4:$C$300,A28) -> 6 | C28: =COUNTIFS(Checklist!$C$4:$C$300,A28,Checklist!$A$4:$A$300,"Done") -> 0 | D28: =COUNTIFS(Checklist!$C$4:$C$300,A28,Checklist!$A$4:$A$300,"N/A") -> 0 | E28: =B28-D28 -> 6 | F28: =IF(E28=0,0,C28/E28) -> 0 | G28: =COUNTIFS(Checklist!$C$4:$C$300,A28,Checklist!$J$4:$J$300,"Direct") -> 6 | H28: =COUNTIFS(Checklist!$C$4:$C$300,A28,Checklist!$J$4:$J$300,"Sensor-specific") -> 0 | I28: =COUNTIFS(Checklist!$C$4:$C$300,A28,Checklist!$B$4:$B$300,"<>",Checklist!$X$4:$X$300,"") -> 6
A31: How to read Source fit
A32: Direct | B32: The source explicitly specifies the feature, algorithm, interface or test method.
A33: Pattern adaptation | B33: The source provides a sound implementation pattern that must be extended to the stated product axis or policy.
A34: Sensor-specific | B34: Public material explains the mechanism, but the named sensor-vendor artifact and target-hardware calibration are mandatory.

Sheet Source Library
A1: Source Library
A2: 60 references used by the 151 checklist rows. Publication/revision and accessed date are separate. URL and License URL cells are real external hyperlinks in the delivered XLSX.
A3: ID | B3: Source | C3: Organization / authors | D3: Published / revision | E3: Version | F3: Accessed date | G3: Type | H3: Source role | I3: URL | J3: Pages / sections used | K3: Why this source is useful | L3: License / reuse | M3: License URL | N3: Code copied? | O3: Clean-room required? | P3: Required artifact | Q3: Used by checklist IDs
A4: S01 | B4: Camera Algorithm and Tuning Guide | C4: Raspberry Pi Ltd | D4: 2025 | E4: Living/current page | F4: 2026-08-08 | G4: Official implementation and tuning guide (PDF) | H4: Primary/official | I4: https://datasheets.raspberrypi.com/camera/raspberry-pi-camera-guide.pdf | J4: pp. 11–64 | K4: Control-loop architecture, AWB/AE/AF, denoise, HDR, calibration, tuning, metadata and synchronization. | L4: Reference use; check publisher/source terms before reuse | M4: https://datasheets.raspberrypi.com/camera/raspberry-pi-camera-guide.pdf | N4: No | O4: No special clean-room requirement identified; still perform legal review | P4: None beyond cited public source | Q4: 6, 7, 7a, 9, 10, 12, 13, 14, 15, 16, 17, 18, 19, 20, 21, 22, 23, 24, 25, 26, 27, 28, 36, 38, 39, 40, 42, 45, 50, 52, 53, 54, 61, 62, 64, 66, 68, 83, 84, 86, 87, 88, 89, 90, 91, 92, 93, 94, 95, 96, 98, 99, 101, 102, 103, 104, 106, 107, 111, 120, 126, 136, 139, 143, 144, 145
A5: S02 | B5: Digital Negative (DNG) Specification 1.7.1.0 | C5: Adobe | D5: 2023 | E5: Specification 1.7.1.0 | F5: 2026-08-08 | G5: Official file-format and raw-processing specification (PDF) | H5: Primary/official | I5: https://helpx.adobe.com/content/dam/help/en/camera-raw/digital-negative/jcr_content/root/content/flex/items/position/position-par/download_section_733958301/download-1/DNG_Spec_1_7_1_0.pdf | J5: pp. 26–62, 71–120 | K5: Raw normalization, calibration tags, color transforms, lens/defect opcodes and processing order. | L5: DNG specification and patent license; review Adobe terms | M5: https://helpx.adobe.com/camera-raw/digital-negative.html | N5: No | O5: No special clean-room requirement identified; still perform legal review | P5: None beyond cited public source | Q5: 1, 2, 3, 4, 5, 7, 7a, 8, 9, 29, 31, 48, 50, 56, 57, 60, 67, 89, 97, 105, 108, 109, 119, 122, 123, 124, 142, 147, 148
A6: S03 | B6: V4L2 RKISP1 parameters and 3A statistics | C6: Linux kernel documentation | D6: 2026 | E6: Living/current page | F6: 2026-08-08 | G6: Official kernel interface documentation | H6: Primary/official | I6: https://docs.kernel.org/userspace-api/media/v4l/metafmt-rkisp1.html | J6: §§2.13.9.1–2.13.9.2 and named structs | K6: Concrete statistics, black-level, defect correction, AWB, filter, demosaic and range-control interfaces. | L6: Reference use; check publisher/source terms before reuse | M6: https://docs.kernel.org/userspace-api/media/v4l/metafmt-rkisp1.html | N6: No | O6: No special clean-room requirement identified; still perform legal review | P6: None beyond cited public source | Q6: 4, 11, 12, 14, 15, 19, 43, 45, 48, 59, 63, 103, 105, 112, 113, 114
A7: S04 | B7: ARM Mali-C55 Image Signal Processor driver | C7: Linux kernel documentation | D7: 2026 | E7: Living/current page | F7: 2026-08-08 | G7: Official kernel driver documentation | H7: Primary/official | I7: https://docs.kernel.org/admin-guide/media/mali-c55.html | J7: §§7.12.2–7.12.4.5 | K7: Crop, scale, YUV, dual-output paths, RAW bypass and processing bypass examples. | L7: Reference use; check publisher/source terms before reuse | M7: https://docs.kernel.org/admin-guide/media/mali-c55.html | N7: No | O7: No special clean-room requirement identified; still perform legal review | P7: None beyond cited public source | Q7: 69, 70, 71, 72, 78, 106
A8: S05 | B8: High Dynamic Range Imaging | C8: OpenCV | D8: 2026 | E8: Living/current page | F8: 2026-08-08 | G8: Official software tutorial | H8: Primary/official | I8: https://docs.opencv.org/4.x/d2/df0/tutorial_py_hdr.html | J8: Exposure fusion, HDR merge and tone-mapping sections | K8: Python-callable exposure calibration, merge and tone-mapping workflow. | L8: Apache-2.0 project documentation/code | M8: https://github.com/opencv/opencv/blob/4.x/LICENSE | N8: No | O8: No special clean-room requirement identified; still perform legal review | P8: None beyond cited public source | Q8: 28, 29, 31
A9: S06 | B9: Robust Patch-Based HDR Reconstruction of Dynamic Scenes | C9: Sen et al., ACM SIGGRAPH Asia | D9: 2012 | E9: Living/current page | F9: 2026-08-08 | G9: Primary research paper (PDF) | H9: Primary research | I9: https://people.engr.tamu.edu/nimak/Data/SIGASIA12_HDR_PatchBasedReconstruction.pdf | J9: pp. 2–7 | K9: Joint alignment, reconstruction, motion handling and deghosting implementation. | L9: Reference use; check publisher/source terms before reuse | M9: https://people.engr.tamu.edu/nimak/Data/SIGASIA12_HDR_PatchBasedReconstruction.pdf | N9: No | O9: No special clean-room requirement identified; still perform legal review | P9: None beyond cited public source | Q9: 30, 32, 121
A10: S07 | B10: Photographic Tone Reproduction for Digital Images | C10: Reinhard et al. | D10: 2002 | E10: Living/current page | F10: 2026-08-08 | G10: Primary research paper (PDF) | H10: Primary research | I10: https://web.tecgraf.puc-rio.br/~scuri/inf1378/pub/reinhard.pdf | J10: pp. 3–5 | K10: Global and local tone mapping, highlight roll-off and shadow/detail control equations. | L10: Reference use; check publisher/source terms before reuse | M10: https://web.tecgraf.puc-rio.br/~scuri/inf1378/pub/reinhard.pdf | N10: No | O10: No special clean-room requirement identified; still perform legal review | P10: None beyond cited public source | Q10: 33, 34, 35, 36, 65
A11: S08 | B11: Recommendation ITU-R BT.2100-3 | C11: International Telecommunication Union | D11: 2025 | E11: Living/current page | F11: 2026-08-08 | G11: Official international recommendation (PDF) | H11: Primary/official | I11: https://www.itu.int/dms_pubrec/itu-r/rec/bt/R-REC-BT.2100-3-202502-I%21%21PDF-E.pdf | J11: pp. 3–10 | K11: PQ/HLG transfer functions, colorimetry, subsampling and legal/full digital ranges. | L11: Reference use; check publisher/source terms before reuse | M11: https://www.itu.int/dms_pubrec/itu-r/rec/bt/R-REC-BT.2100-3-202502-I%21%21PDF-E.pdf | N11: No | O11: No special clean-room requirement identified; still perform legal review | P11: None beyond cited public source | Q11: 37, 72
